<sdf version='1.6'>
  <model name='jamal_description'>
    <joint name='base_static_joint' type='fixed'>
      <pose relative_to='__model__'>0 0 0 0 -0 0</pose>
      <parent>world</parent>
      <child>body</child>
    </joint>
    <link name='body'>
      <!-- <pose relative_to='base_static_joint'>0 0 0 0 -0 0</pose> -->
      <pose frame=''>0 0 0 0 -0 0</pose>
      <inertial>
        <pose>0 0 0 0 -0 0</pose>
        <mass>12.8195</mass>
        <inertia>
          <ixx>0.0566668</ixx>
          <ixy>-8.54732e-06</ixy>
          <ixz>3.4116e-05</ixz>
          <iyy>0.0365645</iyy>
          <iyz>-4.86965e-06</iyz>
          <izz>0.0738589</izz>
        </inertia>
      </inertial>
      <collision name='body_collision'>
        <pose>0 0 0 0 -0 0</pose>
        <geometry>
          <box>
            <size>0.3762 0.0935 0.114</size>
          </box>
        </geometry>
        <surface>
          <contact>
            <ode/>
          </contact>
          <friction>
            <ode/>
          </friction>
        </surface>
      </collision>
      <visual name='body_visual_visual_1'>
        <pose>0 0 0 0 -0 0</pose>
        <geometry>
          <box>
            <size>0.001 0.001 0.001</size>
          </box>
        </geometry>
        <material>
          <script>
            <name>Gazebo/Green</name>
            <uri>file://media/materials/scripts/gazebo.material</uri>
          </script>
        </material>
      </visual>
      <visual name='body_visual'>
        <pose>0 0 0 0 -0 0</pose>
        <geometry>
          <mesh>
            <scale>1 1 1</scale>
            <uri>model:///meshes/trunk.dae</uri>
          </mesh>
        </geometry>
        <material>
          <script>
            <name>Gazebo/DarkGrey</name>
            <uri>file://media/materials/scripts/gazebo.material</uri>
          </script>
        </material>
      </visual>
      <visual name='body_fixed_joint_lump__imu_link_visual_2'>
        <pose>0 0 0 0 -0 0</pose>
        <geometry>
          <box>
            <size>0.001 0.001 0.001</size>
          </box>
        </geometry>
        <material>
          <script>
            <name>Gazebo/Red</name>
            <uri>file://media/materials/scripts/gazebo.material</uri>
          </script>
        </material>
      </visual>
      <sensor name='imu_sensor' type='imu'>
        <always_on>1</always_on>
        <update_rate>1000</update_rate>
        <visualize>1</visualize>
        <topic>__default_topic__</topic>
        <plugin name='imu_plugin' filename='libgazebo_ros_imu_sensor.so'>
          <topicName>trunk_imu</topicName>
          <bodyName>imu_link</bodyName>
          <updateRateHZ>1000.0</updateRateHZ>
          <gaussianNoise>0.0</gaussianNoise>
          <xyzOffset>0 0 0</xyzOffset>
          <rpyOffset>0 0 0</rpyOffset>
          <frameName>imu_link</frameName>
        </plugin>
        <pose>0 0 0 0 -0 0</pose>
      </sensor>
      <gravity>1</gravity>
    </link>
    <joint name='10' type='revolute'>
      <pose relative_to='body'>0.2699 -0.08028 0 0 -0 0</pose>
      <parent>body</parent>
      <child>hip2</child>
      <axis>
        <xyz>1 0 0</xyz>
        <limit>
          <lower>-0.436332</lower>
          <upper>0.436332</upper>
          <effort>48</effort>
          <velocity>8</velocity>
        </limit>
        <dynamics>
          <damping>0.01</damping>
          <friction>0.2</friction>
          <spring_reference>0</spring_reference>
          <spring_stiffness>0</spring_stiffness>
        </dynamics>
      </axis>
    </joint>
    <link name='hip2'>
      <pose relative_to='10'>0 0 0 0 -0 0</pose>
      <inertial>
        <pose>0 0 0 0 -0 0</pose>
        <mass>0.933763</mass>
        <inertia>
          <ixx>0.000832274</ixx>
          <ixy>-2.01743e-06</ixy>
          <ixz>-9.96248e-07</ixz>
          <iyy>0.00106512</iyy>
          <iyz>3.2766e-06</iyz>
          <izz>0.00080368</izz>
        </inertia>
      </inertial>
      <collision name='hip2_collision_collision'>
        <pose>0 0 0 1.5708 -0 0</pose>
        <geometry>
          <cylinder>
            <length>0.04</length>
            <radius>0.046</radius>
          </cylinder>
        </geometry>
        <surface>
          <contact>
            <ode/>
          </contact>
          <friction>
            <ode>
              <mu>0.2</mu>
              <mu2>0.2</mu2>
            </ode>
          </friction>
        </surface>
      </collision>
      <collision name='hip2_fixed_joint_lump__thigh_shoulder2_collision_1'>
        <pose>0 -0.016 0 1.5708 -0 0</pose>
        <geometry>
          <cylinder>
            <length>0.032</length>
            <radius>0.041</radius>
          </cylinder>
        </geometry>
      </collision>
      <visual name='hip2_visual_visual'>
        <pose>0 0 0 3.14159 -0 0</pose>
        <geometry>
          <mesh>
            <scale>1 1 1</scale>
            <uri>model:///meshes/hip.dae</uri>
          </mesh>
        </geometry>
        <material>
          <script>
            <name>Gazebo/DarkGrey</name>
            <uri>file://media/materials/scripts/gazebo.material</uri>
          </script>
        </material>
      </visual>
      <gravity>1</gravity>
    </link>
    <joint name='4' type='revolute'>
      <pose relative_to='hip2'>0 -0.10755 0 0 1.5708 0</pose>
      <parent>hip2</parent>
      <child>upper2</child>
      <axis>
        <xyz>0 -1 0</xyz>
        <limit>
          <lower>-1.5708</lower>
          <upper>1.5708</upper>
          <effort>48</effort>
          <velocity>8</velocity>
        </limit>
        <dynamics>
          <damping>0.01</damping>
          <friction>0.2</friction>
          <spring_reference>0</spring_reference>
          <spring_stiffness>0</spring_stiffness>
        </dynamics>
      </axis>
    </joint>
    <link name='upper2'>
      <pose relative_to='4'>0 0 0 0 -0 0</pose>
      <inertial>
        <pose>0 0 0 0 -0 0</pose>
        <mass>1.32134</mass>
        <inertia>
          <ixx>0.00262881</ixx>
          <ixy>-3.0753e-07</ixy>
          <ixz>-6.61219e-05</ixz>
          <iyy>0.00316092</iyy>
          <iyz>-4.01609e-05</iyz>
          <izz>0.00121962</izz>
        </inertia>
      </inertial>
      <collision name='upper2_collision_collision'>
        <pose>0 0 -0.1125 0 1.5708 0</pose>
        <geometry>
          <box>
            <size>0.225 0.0245 0.034</size>
          </box>
        </geometry>
        <surface>
          <contact>
            <ode>
              <kp>1e+06</kp>
              <kd>1</kd>
            </ode>
          </contact>
          <friction>
            <ode>
              <mu>0.2</mu>
              <mu2>0.2</mu2>
            </ode>
          </friction>
        </surface>
      </collision>
      <visual name='upper2_visual_visual'>
        <pose>0 0 0 0 -0 0</pose>
        <geometry>
          <mesh>
            <scale>1 1 1</scale>
            <uri>model:///meshes/thigh_mirror.dae</uri>
          </mesh>
        </geometry>
        <material>
          <script>
            <name>Gazebo/DarkGrey</name>
            <uri>file://media/materials/scripts/gazebo.material</uri>
          </script>
        </material>
      </visual>
      <gravity>1</gravity>
    </link>
    <joint name='5' type='revolute'>
      <pose relative_to='upper2'>0 0 -0.225 3.14159 -0 3.14159</pose>
      <parent>upper2</parent>
      <child>lower2</child>
      <axis>
        <xyz>0 1 0</xyz>
        <limit>
          <lower>-2.67035</lower>
          <upper>2.67035</upper>
          <effort>48</effort>
          <velocity>8</velocity>
        </limit>
        <dynamics>
          <damping>0.01</damping>
          <friction>0.2</friction>
          <spring_reference>0</spring_reference>
          <spring_stiffness>0</spring_stiffness>
        </dynamics>
      </axis>
    </joint>
    <link name='lower2'>
      <pose relative_to='5'>0 0 0 0 -0 0</pose>
      <inertial>
        <pose>0 0 -0.079452 0 -0 0</pose>
        <mass>0.188793</mass>
        <inertia>
          <ixx>0.00301049</ixx>
          <ixy>-7.71824e-09</ixy>
          <ixz>7.55837e-05</ixz>
          <iyy>0.00303084</iyy>
          <iyz>4.84096e-09</iyz>
          <izz>3.03639e-05</izz>
        </inertia>
      </inertial>
      <collision name='lower2_collision_collision'>
        <pose>0 0 -0.125 0 1.5708 0</pose>
        <geometry>
          <box>
            <size>0.25 0.016 0.016</size>
          </box>
        </geometry>
        <surface>
          <contact>
            <ode/>
          </contact>
          <friction>
            <ode>
              <mu>0.2</mu>
              <mu2>0.2</mu2>
            </ode>
          </friction>
        </surface>
      </collision>
      <collision name='lower2_fixed_joint_lump__toe2_collision_collision_1'>
        <pose>0 0 -0.25 0 -0 0</pose>
        <geometry>
          <sphere>
            <radius>0.017</radius>
          </sphere>
        </geometry>
        <surface>
          <contact>
            <ode>
              <kp>1e+06</kp>
              <kd>1</kd>
            </ode>
          </contact>
          <friction>
            <ode>
              <mu>0.6</mu>
              <mu2>0.6</mu2>
            </ode>
          </friction>
        </surface>
      </collision>
      <visual name='lower2_visual_visual'>
        <pose>0 0 0 0 -0 0</pose>
        <geometry>
          <mesh>
            <scale>1 1 1</scale>
            <uri>model:///meshes/calf.dae</uri>
          </mesh>
        </geometry>
      </visual>
      <gravity>1</gravity>
      <visual name='lower2_fixed_joint_lump__toe2_visual_visual_1'>
        <pose>0 0 -0.25 0 -0 0</pose>
        <geometry>
          <sphere>
            <radius>0.007</radius>
          </sphere>
        </geometry>
        <material>
          <script>
            <name>Gazebo/DarkGrey</name>
            <uri>file://media/materials/scripts/gazebo.material</uri>
          </script>
        </material>
      </visual>
      <sensor name='toe2_contact' type='contact'>
        <plugin name='toe2_plugin' filename='libgazebo_ros_bumper.so'>
          <alwaysOn>1</alwaysOn>
          <updateRate>500</updateRate>
          <bumperTopicName>gazebo/toe2_contact_state</bumperTopicName>
          <frameName>world</frameName>
        </plugin>
        <contact>
          <collision>lower2_collision_toe2</collision>
          <topic>__default_topic__</topic>
        </contact>
        <update_rate>500</update_rate>
        <pose>0 0 -0.25 0 -0 0</pose>
      </sensor>
      <gravity>1</gravity>
    </link>
    <joint name='11' type='revolute'>
      <pose relative_to='body'>-0.2699 -0.08028 0 0 -0 0</pose>
      <parent>body</parent>
      <child>hip3</child>
      <axis>
        <xyz>1 0 0</xyz>
        <limit>
          <lower>-0.436332</lower>
          <upper>0.436332</upper>
          <effort>48</effort>
          <velocity>8</velocity>
        </limit>
        <dynamics>
          <damping>0.01</damping>
          <friction>0.2</friction>
          <spring_reference>0</spring_reference>
          <spring_stiffness>0</spring_stiffness>
        </dynamics>
      </axis>
    </joint>
    <link name='hip3'>
      <pose relative_to='11'>0 0 0 0 -0 0</pose>
      <inertial>
        <pose>0 0 0 0 -0 0</pose>
        <mass>0.933763</mass>
        <inertia>
          <ixx>0.000832274</ixx>
          <ixy>2.01743e-06</ixy>
          <ixz>9.96248e-07</ixz>
          <iyy>0.00106512</iyy>
          <iyz>3.2766e-06</iyz>
          <izz>0.00080368</izz>
        </inertia>
      </inertial>
      <collision name='hip3_collision_collision'>
        <pose>0 0 0 1.5708 -0 0</pose>
        <geometry>
          <cylinder>
            <length>0.04</length>
            <radius>0.046</radius>
          </cylinder>
        </geometry>
        <surface>
          <contact>
            <ode/>
          </contact>
          <friction>
            <ode>
              <mu>0.2</mu>
              <mu2>0.2</mu2>
            </ode>
          </friction>
        </surface>
      </collision>
      <collision name='hip3_fixed_joint_lump__thigh_shoulder3_collision_1'>
        <pose>0 -0.016 0 1.5708 -0 0</pose>
        <geometry>
          <cylinder>
            <length>0.032</length>
            <radius>0.041</radius>
          </cylinder>
        </geometry>
      </collision>
      <visual name='hip3_visual_visual'>
        <pose>0 0 0 -0 0 3.14159</pose>
        <geometry>
          <mesh>
            <scale>1 1 1</scale>
            <uri>model:///meshes/hip.dae</uri>
          </mesh>
        </geometry>
        <material>
          <script>
            <name>Gazebo/DarkGrey</name>
            <uri>file://media/materials/scripts/gazebo.material</uri>
          </script>
        </material>
      </visual>
      <gravity>1</gravity>
    </link>
    <joint name='6' type='revolute'>
      <pose relative_to='hip3'>0 -0.10755 0 0 1.5708 0</pose>
      <parent>hip3</parent>
      <child>upper3</child>
      <axis>
        <xyz>0 -1 0</xyz>
        <limit>
          <lower>-1.5708</lower>
          <upper>1.5708</upper>
          <effort>48</effort>
          <velocity>8</velocity>
        </limit>
        <dynamics>
          <damping>0.01</damping>
          <friction>0.2</friction>
          <spring_reference>0</spring_reference>
          <spring_stiffness>0</spring_stiffness>
        </dynamics>
      </axis>
    </joint>
    <link name='upper3'>
      <pose relative_to='6'>0 0 0 0 -0 0</pose>
      <inertial>
        <pose>0 0 0 0 -0 0</pose>
        <mass>1.32134</mass>
        <inertia>
          <ixx>0.00262881</ixx>
          <ixy>-3.0753e-07</ixy>
          <ixz>-6.61219e-05</ixz>
          <iyy>0.00316092</iyy>
          <iyz>-4.01609e-05</iyz>
          <izz>0.00121962</izz>
        </inertia>
      </inertial>
      <collision name='upper3_collision_collision'>
        <pose>0 0 -0.1125 0 1.5708 0</pose>
        <geometry>
          <box>
            <size>0.225 0.0245 0.034</size>
          </box>
        </geometry>
        <surface>
          <contact>
            <ode>
              <kp>1e+06</kp>
              <kd>1</kd>
            </ode>
          </contact>
          <friction>
            <ode>
              <mu>0.2</mu>
              <mu2>0.2</mu2>
            </ode>
          </friction>
        </surface>
      </collision>
      <visual name='upper3_visual_visual'>
        <pose>0 0 0 0 -0 0</pose>
        <geometry>
          <mesh>
            <scale>1 1 1</scale>
            <uri>model:///meshes/thigh_mirror.dae</uri>
          </mesh>
        </geometry>
        <material>
          <script>
            <name>Gazebo/DarkGrey</name>
            <uri>file://media/materials/scripts/gazebo.material</uri>
          </script>
        </material>
      </visual>
      <gravity>1</gravity>

    </link>
    <joint name='7' type='revolute'>
      <pose relative_to='upper3'>0 0 -0.225 3.14159 -0 3.14159</pose>
      <parent>upper3</parent>
      <child>lower3</child>
      <axis>
        <xyz>0 1 0</xyz>
        <limit>
          <lower>-2.67035</lower>
          <upper>2.67035</upper>
          <effort>48</effort>
          <velocity>8</velocity>
        </limit>
        <dynamics>
          <damping>0.01</damping>
          <friction>0.2</friction>
          <spring_reference>0</spring_reference>
          <spring_stiffness>0</spring_stiffness>
        </dynamics>
      </axis>
    </joint>
    <link name='lower3'>
      <pose relative_to='7'>0 0 0 0 -0 0</pose>
      <inertial>
        <pose>0 0 -0.079452 0 -0 0</pose>
        <mass>0.188793</mass>
        <inertia>
          <ixx>0.00301049</ixx>
          <ixy>-7.71824e-09</ixy>
          <ixz>7.55837e-05</ixz>
          <iyy>0.00303084</iyy>
          <iyz>4.84096e-09</iyz>
          <izz>3.03639e-05</izz>
        </inertia>
      </inertial>
      <collision name='lower3_collision_collision'>
        <pose>0 0 -0.125 0 1.5708 0</pose>
        <geometry>
          <box>
            <size>0.25 0.016 0.016</size>
          </box>
        </geometry>
        <surface>
          <contact>
            <ode/>
          </contact>
          <friction>
            <ode>
              <mu>0.2</mu>
              <mu2>0.2</mu2>
            </ode>
          </friction>
        </surface>
      </collision>
      <collision name='lower3_fixed_joint_lump__toe3_collision_collision_1'>
        <pose>0 0 -0.25 0 -0 0</pose>
        <geometry>
          <sphere>
            <radius>0.017</radius>
          </sphere>
        </geometry>
        <surface>
          <contact>
            <ode>
              <kp>1e+06</kp>
              <kd>1</kd>
            </ode>
          </contact>
          <friction>
            <ode>
              <mu>0.6</mu>
              <mu2>0.6</mu2>
            </ode>
          </friction>
        </surface>
      </collision>
      <visual name='lower3_visual_visual'>
        <pose>0 0 0 0 -0 0</pose>
        <geometry>
          <mesh>
            <scale>1 1 1</scale>
            <uri>model:///meshes/calf.dae</uri>
          </mesh>
        </geometry>
      </visual>
      <visual name='lower3_fixed_joint_lump__toe3_visual_visual_1'>
        <pose>0 0 -0.25 0 -0 0</pose>
        <geometry>
          <sphere>
            <radius>0.007</radius>
          </sphere>
        </geometry>
        <material>
          <script>
            <name>Gazebo/DarkGrey</name>
            <uri>file://media/materials/scripts/gazebo.material</uri>
          </script>
        </material>
      </visual>

      <sensor name='toe3_contact' type='contact'>
        <plugin name='toe3_plugin' filename='libgazebo_ros_bumper.so'>
          <alwaysOn>1</alwaysOn>
          <updateRate>500</updateRate>
          <bumperTopicName>gazebo/toe3_contact_state</bumperTopicName>
          <frameName>world</frameName>
        </plugin>
        <contact>
          <collision>lower3_collision_toe3</collision>
          <topic>__default_topic__</topic>
        </contact>
        <update_rate>500</update_rate>
        <pose>0 0 -0.25 0 -0 0</pose>
      </sensor>
      <gravity>1</gravity>

    </link>
    <joint name='8' type='revolute'>
      <pose relative_to='body'>0.2699 0.08028 0 0 -0 0</pose>
      <parent>body</parent>
      <child>hip0</child>
      <axis>
        <xyz>1 0 0</xyz>
        <limit>
          <lower>-0.436332</lower>
          <upper>0.436332</upper>
          <effort>48</effort>
          <velocity>8</velocity>
        </limit>
        <dynamics>
          <damping>0.01</damping>
          <friction>0.2</friction>
          <spring_reference>0</spring_reference>
          <spring_stiffness>0</spring_stiffness>
        </dynamics>
      </axis>
    </joint>
    <link name='hip0'>
      <pose relative_to='8'>0 0 0 0 -0 0</pose>
      <inertial>
        <pose>0 0 0 0 -0 0</pose>
        <mass>0.933763</mass>
        <inertia>
          <ixx>0.000832274</ixx>
          <ixy>2.01743e-06</ixy>
          <ixz>-9.96248e-07</ixz>
          <iyy>0.00106512</iyy>
          <iyz>-3.2766e-06</iyz>
          <izz>0.00080368</izz>
        </inertia>
      </inertial>
      <collision name='hip0_collision_collision'>
        <pose>0 0 0 1.5708 -0 0</pose>
        <geometry>
          <cylinder>
            <length>0.04</length>
            <radius>0.046</radius>
          </cylinder>
        </geometry>
        <surface>
          <contact>
            <ode/>
          </contact>
          <friction>
            <ode>
              <mu>0.2</mu>
              <mu2>0.2</mu2>
            </ode>
          </friction>
        </surface>
      </collision>
      <collision name='hip0_fixed_joint_lump__thigh_shoulder0_collision_1'>
        <pose>0 0.016 0 1.5708 -0 0</pose>
        <geometry>
          <cylinder>
            <length>0.032</length>
            <radius>0.041</radius>
          </cylinder>
        </geometry>
      </collision>
      <visual name='hip0_visual_visual'>
        <pose>0 0 0 0 -0 0</pose>
        <geometry>
          <mesh>
            <scale>1 1 1</scale>
            <uri>model:///meshes/hip.dae</uri>
          </mesh>
        </geometry>
        <material>
          <script>
            <name>Gazebo/DarkGrey</name>
            <uri>file://media/materials/scripts/gazebo.material</uri>
          </script>
        </material>
      </visual>
      <gravity>1</gravity>
    </link>
    <joint name='0' type='revolute'>
      <pose relative_to='hip0'>0 0.10755 0 0 1.5708 0</pose>
      <parent>hip0</parent>
      <child>upper0</child>
      <axis>
        <xyz>0 -1 0</xyz>
        <limit>
          <lower>-1.5708</lower>
          <upper>1.5708</upper>
          <effort>48</effort>
          <velocity>8</velocity>
        </limit>
        <dynamics>
          <damping>0.01</damping>
          <friction>0.2</friction>
          <spring_reference>0</spring_reference>
          <spring_stiffness>0</spring_stiffness>
        </dynamics>
      </axis>
    </joint>
    <link name='upper0'>
      <pose relative_to='0'>0 0 0 0 -0 0</pose>
      <inertial>
        <pose>0 0 0 0 -0 0</pose>
        <mass>1.32134</mass>
        <inertia>
          <ixx>0.00262881</ixx>
          <ixy>3.0753e-07</ixy>
          <ixz>-6.61219e-05</ixz>
          <iyy>0.00316092</iyy>
          <iyz>4.01609e-05</iyz>
          <izz>0.00121962</izz>
        </inertia>
      </inertial>
      <collision name='upper0_collision_collision'>
        <pose>0 0 -0.1125 0 1.5708 0</pose>
        <geometry>
          <box>
            <size>0.225 0.0245 0.034</size>
          </box>
        </geometry>
        <surface>
          <contact>
            <ode>
              <kp>1e+06</kp>
              <kd>1</kd>
            </ode>
          </contact>
          <friction>
            <ode>
              <mu>0.2</mu>
              <mu2>0.2</mu2>
            </ode>
          </friction>
        </surface>
      </collision>
      <visual name='upper0_visual_visual'>
        <pose>0 0 0 0 -0 0</pose>
        <geometry>
          <mesh>
            <scale>1 1 1</scale>
            <uri>model:///meshes/thigh.dae</uri>
          </mesh>
        </geometry>
        <material>
          <script>
            <name>Gazebo/DarkGrey</name>
            <uri>file://media/materials/scripts/gazebo.material</uri>
          </script>
        </material>
      </visual>
      <gravity>1</gravity>

    </link>
    <joint name='1' type='revolute'>
      <pose relative_to='upper0'>0 0 -0.225 3.14159 -0 3.14159</pose>
      <parent>upper0</parent>
      <child>lower0</child>
      <axis>
        <xyz>0 1 0</xyz>
        <limit>
          <lower>-2.67035</lower>
          <upper>2.67035</upper>
          <effort>48</effort>
          <velocity>8</velocity>
        </limit>
        <dynamics>
          <damping>0.01</damping>
          <friction>0.2</friction>
          <spring_reference>0</spring_reference>
          <spring_stiffness>0</spring_stiffness>
        </dynamics>
      </axis>
    </joint>
    <link name='lower0'>
      <pose relative_to='1'>0 0 0 0 -0 0</pose>
      <inertial>
        <pose>0 0 -0.079452 0 -0 0</pose>
        <mass>0.188793</mass>
        <inertia>
          <ixx>0.00301049</ixx>
          <ixy>-7.71824e-09</ixy>
          <ixz>7.55837e-05</ixz>
          <iyy>0.00303084</iyy>
          <iyz>4.84096e-09</iyz>
          <izz>3.03639e-05</izz>
        </inertia>
      </inertial>
      <collision name='lower0_collision_collision'>
        <pose>0 0 -0.125 0 1.5708 0</pose>
        <geometry>
          <box>
            <size>0.25 0.016 0.016</size>
          </box>
        </geometry>
        <surface>
          <contact>
            <ode/>
          </contact>
          <friction>
            <ode>
              <mu>0.2</mu>
              <mu2>0.2</mu2>
            </ode>
          </friction>
        </surface>
      </collision>
      <collision name='lower0_fixed_joint_lump__toe0_collision_collision_1'>
        <pose>0 0 -0.25 0 -0 0</pose>
        <geometry>
          <sphere>
            <radius>0.017</radius>
          </sphere>
        </geometry>
        <surface>
          <contact>
            <ode>
              <kp>1e+06</kp>
              <kd>1</kd>
            </ode>
          </contact>
          <friction>
            <ode>
              <mu>0.6</mu>
              <mu2>0.6</mu2>
            </ode>
          </friction>
        </surface>
      </collision>
      <visual name='lower0_visual_visual'>
        <pose>0 0 0 0 -0 0</pose>
        <geometry>
          <mesh>
            <scale>1 1 1</scale>
            <uri>model:///meshes/calf.dae</uri>
          </mesh>
        </geometry>
      </visual>
      <visual name='lower0_fixed_joint_lump__toe0_visual_visual_1'>
        <pose>0 0 -0.25 0 -0 0</pose>
        <geometry>
          <sphere>
            <radius>0.007</radius>
          </sphere>
        </geometry>
        <material>
          <script>
            <name>Gazebo/DarkGrey</name>
            <uri>file://media/materials/scripts/gazebo.material</uri>
          </script>
        </material>
      </visual>

      <sensor name='toe0_contact' type='contact'>
        <plugin name='toe0_plugin' filename='libgazebo_ros_bumper.so'>
          <alwaysOn>1</alwaysOn>
          <updateRate>500</updateRate>
          <bumperTopicName>gazebo/toe0_contact_state</bumperTopicName>
          <frameName>world</frameName>
        </plugin>
        <contact>
          <collision>lower0_collision_toe0</collision>
          <topic>__default_topic__</topic>
        </contact>
        <update_rate>500</update_rate>
        <pose>0 0 -0.25 0 -0 0</pose>
      </sensor>
      <gravity>1</gravity>

    </link>
    <joint name='9' type='revolute'>
      <pose relative_to='body'>-0.2699 0.08028 0 0 -0 0</pose>
      <parent>body</parent>
      <child>hip1</child>
      <axis>
        <xyz>1 0 0</xyz>
        <limit>
          <lower>-0.436332</lower>
          <upper>0.436332</upper>
          <effort>48</effort>
          <velocity>8</velocity>
        </limit>
        <dynamics>
          <damping>0.01</damping>
          <friction>0.2</friction>
          <spring_reference>0</spring_reference>
          <spring_stiffness>0</spring_stiffness>
        </dynamics>
      </axis>
    </joint>
    <link name='hip1'>
      <pose relative_to='9'>0 0 0 0 -0 0</pose>
      <inertial>
        <pose>0 0 0 0 -0 0</pose>
        <mass>0.933763</mass>
        <inertia>
          <ixx>0.000832274</ixx>
          <ixy>-2.01743e-06</ixy>
          <ixz>9.96248e-07</ixz>
          <iyy>0.00106512</iyy>
          <iyz>-3.2766e-06</iyz>
          <izz>0.00080368</izz>
        </inertia>
      </inertial>
      <collision name='hip1_collision_collision'>
        <pose>0 0 0 1.5708 -0 0</pose>
        <geometry>
          <cylinder>
            <length>0.04</length>
            <radius>0.046</radius>
          </cylinder>
        </geometry>
        <surface>
          <contact>
            <ode/>
          </contact>
          <friction>
            <ode>
              <mu>0.2</mu>
              <mu2>0.2</mu2>
            </ode>
          </friction>
        </surface>
      </collision>
      <collision name='hip1_fixed_joint_lump__thigh_shoulder1_collision_1'>
        <pose>0 0.016 0 1.5708 -0 0</pose>
        <geometry>
          <cylinder>
            <length>0.032</length>
            <radius>0.041</radius>
          </cylinder>
        </geometry>
      </collision>
      <visual name='hip1_visual_visual'>
        <pose>0 0 0 3.14159 0 3.14159</pose>
        <geometry>
          <mesh>
            <scale>1 1 1</scale>
            <uri>model:///meshes/hip.dae</uri>
          </mesh>
        </geometry>
        <material>
          <script>
            <name>Gazebo/DarkGrey</name>
            <uri>file://media/materials/scripts/gazebo.material</uri>
          </script>
        </material>
      </visual>
      <gravity>1</gravity>
    </link>
    <joint name='2' type='revolute'>
      <pose relative_to='hip1'>0 0.10755 0 0 1.5708 0</pose>
      <parent>hip1</parent>
      <child>upper1</child>
      <axis>
        <xyz>0 -1 0</xyz>
        <limit>
          <lower>-1.5708</lower>
          <upper>1.5708</upper>
          <effort>48</effort>
          <velocity>8</velocity>
        </limit>
        <dynamics>
          <damping>0.01</damping>
          <friction>0.2</friction>
          <spring_reference>0</spring_reference>
          <spring_stiffness>0</spring_stiffness>
        </dynamics>
      </axis>
    </joint>
    <link name='upper1'>
      <pose relative_to='2'>0 0 0 0 -0 0</pose>
      <inertial>
        <pose>0 0 0 0 -0 0</pose>
        <mass>1.32134</mass>
        <inertia>
          <ixx>0.00262881</ixx>
          <ixy>3.0753e-07</ixy>
          <ixz>-6.61219e-05</ixz>
          <iyy>0.00316092</iyy>
          <iyz>4.01609e-05</iyz>
          <izz>0.00121962</izz>
        </inertia>
      </inertial>
      <collision name='upper1_collision_collision'>
        <pose>0 0 -0.1125 0 1.5708 0</pose>
        <geometry>
          <box>
            <size>0.225 0.0245 0.034</size>
          </box>
        </geometry>
        <surface>
          <contact>
            <ode>
              <kp>1e+06</kp>
              <kd>1</kd>
            </ode>
          </contact>
          <friction>
            <ode>
              <mu>0.2</mu>
              <mu2>0.2</mu2>
            </ode>
          </friction>
        </surface>
      </collision>
      <visual name='upper1_visual_visual'>
        <pose>0 0 0 0 -0 0</pose>
        <geometry>
          <mesh>
            <scale>1 1 1</scale>
            <uri>model:///meshes/thigh.dae</uri>
          </mesh>
        </geometry>
        <material>
          <script>
            <name>Gazebo/DarkGrey</name>
            <uri>file://media/materials/scripts/gazebo.material</uri>
          </script>
        </material>
      </visual>
      <gravity>1</gravity>

    </link>
    <joint name='3' type='revolute'>
      <pose relative_to='upper1'>0 0 -0.225 3.14159 -0 3.14159</pose>
      <parent>upper1</parent>
      <child>lower1</child>
      <axis>
        <xyz>0 1 0</xyz>
        <limit>
          <lower>-2.67035</lower>
          <upper>2.67035</upper>
          <effort>48</effort>
          <velocity>8</velocity>
        </limit>
        <dynamics>
          <damping>0.01</damping>
          <friction>0.2</friction>
          <spring_reference>0</spring_reference>
          <spring_stiffness>0</spring_stiffness>
        </dynamics>
      </axis>
    </joint>
    <link name='lower1'>
      <pose relative_to='3'>0 0 0 0 -0 0</pose>
      <inertial>
        <pose>0 0 -0.079452 0 -0 0</pose>
        <mass>0.188793</mass>
        <inertia>
          <ixx>0.00301049</ixx>
          <ixy>-7.71824e-09</ixy>
          <ixz>7.55837e-05</ixz>
          <iyy>0.00303084</iyy>
          <iyz>4.84096e-09</iyz>
          <izz>3.03639e-05</izz>
        </inertia>
      </inertial>
      <collision name='lower1_collision_collision'>
        <pose>0 0 -0.125 0 1.5708 0</pose>
        <geometry>
          <box>
            <size>0.25 0.016 0.016</size>
          </box>
        </geometry>
        <surface>
          <contact>
            <ode/>
          </contact>
          <friction>
            <ode>
              <mu>0.2</mu>
              <mu2>0.2</mu2>
            </ode>
          </friction>
        </surface>
      </collision>
      <collision name='lower1_fixed_joint_lump__toe1_collision_collision_1'>
        <pose>0 0 -0.25 0 -0 0</pose>
        <geometry>
          <sphere>
            <radius>0.017</radius>
          </sphere>
        </geometry>
        <surface>
          <contact>
            <ode>
              <kp>1e+06</kp>
              <kd>1</kd>
            </ode>
          </contact>
          <friction>
            <ode>
              <mu>0.6</mu>
              <mu2>0.6</mu2>
            </ode>
          </friction>
        </surface>
      </collision>
      <visual name='lower1_visual_visual'>
        <pose>0 0 0 0 -0 0</pose>
        <geometry>
          <mesh>
            <scale>1 1 1</scale>
            <uri>model:///meshes/calf.dae</uri>
          </mesh>
        </geometry>
      </visual>
      <visual name='lower1_fixed_joint_lump__toe1_visual_visual_1'>
        <pose>0 0 -0.25 0 -0 0</pose>
        <geometry>
          <sphere>
            <radius>0.007</radius>
          </sphere>
        </geometry>
        <material>
          <script>
            <name>Gazebo/DarkGrey</name>
            <uri>file://media/materials/scripts/gazebo.material</uri>
          </script>
        </material>
      </visual>

      <sensor name='toe1_contact' type='contact'>
        <plugin name='toe1_plugin' filename='libgazebo_ros_bumper.so'>
          <alwaysOn>1</alwaysOn>
          <updateRate>500</updateRate>
          <bumperTopicName>gazebo/toe1_contact_state</bumperTopicName>
          <frameName>world</frameName>
        </plugin>
        <contact>
          <collision>lower1_collision_toe1</collision>
          <topic>__default_topic__</topic>
        </contact>
        <update_rate>500</update_rate>
        <pose>0 0 -0.25 0 -0 0</pose>
      </sensor>
      <gravity>1</gravity>

    </link>

  <!-- Publish imu sensor readings -->
    <include>
      <uri>model://imu</uri>
      <pose>0 0 0 0 0 0 </pose>
    </include>
    <joint name="imu_joint" type="fixed">
      <child>imu::link</child>
      <parent>body</parent>
    </joint>

    <plugin name='gazebo_ros_control' filename='libgazebo_ros_control.so'>
      <!-- <controlPeriod>0.002</controlPeriod> -->
      <robotNamespace>/robot_1</robotNamespace>
      <robotSimType>gazebo_ros_control/DefaultRobotHWSim</robotSimType>
    </plugin>
    <plugin name='ground_truth_estimator' filename='libground_truth_estimator.so'>
      <updateRateHZ>500.0</updateRateHZ>
    </plugin>
    <static>0</static>
    <plugin name='gazebo_ros_force' filename='libgazebo_ros_force.so'>
      <topicName>/apply_force/trunk</topicName>
      <bodyName>body</bodyName>
      <xyzOffset>0 0 0</xyzOffset>
      <rpyOffset>0 -0 0</rpyOffset>
      <!-- <ignition::corrected_offsets>1</ignition::corrected_offsets> -->
    </plugin>
    <frame name='imu_joint' attached_to='trunk'>
      <pose>0 0 0 0 -0 0</pose>
    </frame>
    <frame name='imu_link' attached_to='imu_joint'/>
    <frame name='floating_base' attached_to='body'>
      <pose>0 0 0 0 -0 0</pose>
    </frame>
    <frame name='trunk' attached_to='floating_base'/>
    <frame name='hip2_fixed' attached_to='hip2'>
      <pose>0 -0.016 0 0 -0 0</pose>
    </frame>
    <frame name='thigh_shoulder2' attached_to='hip2_fixed'/>
    <frame name='jtoe2' attached_to='lower2'>
      <pose>0 0 -0.25 0 -0 0</pose>
    </frame>
    <frame name='toe2' attached_to='jtoe2'/>
    <frame name='hip3_fixed' attached_to='hip3'>
      <pose>0 -0.016 0 0 -0 0</pose>
    </frame>
    <frame name='thigh_shoulder3' attached_to='hip3_fixed'/>
    <frame name='jtoe3' attached_to='lower3'>
      <pose>0 0 -0.25 0 -0 0</pose>
    </frame>
    <frame name='toe3' attached_to='jtoe3'/>
    <frame name='hip0_fixed' attached_to='hip0'>
      <pose>0 0.016 0 0 -0 0</pose>
    </frame>
    <frame name='thigh_shoulder0' attached_to='hip0_fixed'/>
    <frame name='jtoe0' attached_to='lower0'>
      <pose>0 0 -0.25 0 -0 0</pose>
    </frame>
    <frame name='toe0' attached_to='jtoe0'/>
    <frame name='hip1_fixed' attached_to='hip1'>
      <pose>0 0.016 0 0 -0 0</pose>
    </frame>
    <frame name='thigh_shoulder1' attached_to='hip1_fixed'/>
    <frame name='jtoe1' attached_to='lower1'>
      <pose>0 0 -0.25 0 -0 0</pose>
    </frame>
    <frame name='toe1' attached_to='jtoe1'/>
    
  </model>
</sdf>
